    Traceback (most recent call last):
  File "/home/kirill/.local/lib/python3.13/site-packages/pydantic/main.py", line 983, in __getattr__
    return pydantic_extra[item]
           ~~~~~~~~~~~~~~^^^^^^
KeyError: 'images'

The above exception was the direct cause of the following exception:

Traceback (most recent call last):
  File "/home/kirill/Side-Projects/ContentMachine/main.py", line 19, in <module>
    telegram_bot.text_to_image("Тяжёлый свэг, бро \
    ~~~~~~~~~~~~~~~~~~~~~~~~~~^^^^^^^^^^^^^^^^^^^^^
                Оппам достаётся лишь конец, бро, о \
                ^^^^^^^^^^^^^^^^^^^^^^^^^^^^^^^^^^^^
    ...<4 lines>...
                Что ты делаешь со мной? \
                ^^^^^^^^^^^^^^^^^^^^^^^^^
                Что ты делаешь со мной?")
                ^^^^^^^^^^^^^^^^^^^^^^^^^
  File "/home/kirill/Side-Projects/ContentMachine/telegram_bot.py", line 111, in text_to_image
    print(completion.choices[0].images.url)
          ^^^^^^^^^^^^^^^^^^^^^^^^^^^^
  File "/home/kirill/.local/lib/python3.13/site-packages/pydantic/main.py", line 985, in __getattr__
    raise AttributeError(f'{type(self).__name__!r} object has no attribute {item!r}') from exc
AttributeError: 'Choice' object has no attribute 'images'
